Workbook

Sheet Affinity
A1: Table 1
A2: Affinity | B2: Key strength
A3: Divine | B3: High defense, Anti-Chaos bonus
A4: Chaos | B4: High cost, powerful units
A5: Arcane | B5: Spending a lot of Crystal to maximize power in short time. A glass cannon.
A6: Nature | B6: Balanced, Union heavy
A7: Bio | B7: Few unit, mutate to other or attack a lot of times, Tech heavy
A8: Cosmic | B8: High discovery capacity, Tech heavy
A9: Anima | B9: Low cost, swarming

Sheet Unit
A1: Table 1
A2: Card Name | B2: Card Type | C2: Cost | D2: ATK | E2: DEF | F2: Affinity | G2: Rarity | H2: Ability | I2: Comment | J2: Formula | K2: Have illustration | L2: Suggested cost | M2: Demo | N2: Test 1 | O2: ="Booster Pack - Blightsilver / "&COUNTIF(N3:N568,"Yes") | P2: ="Booster Pack - Unseen Presence / "&COUNTIF(O3:O568,"Yes") | Q2: ="Booster Pack - Wind of Dominance / "&COUNTIF(P3:P568,"Yes")
A3: Pyromancer | B3: Unit | C3: 900 | D3: 80 | E3: 0 | F3: Arcane | G3: 4 | H3: +30 ATK vs Nature | I3: dropped redundant Affinity | K3: Yes | L3: =(D3*6)+(E3*4) | M3: Yes | Q3: Yes
A4: Angel Gatekeeper | B4: Unit | C4: 1000 | D4: 40 | E4: 90 | F4: Divine | G4: 4 | H4: +50 ATK vs Chaos | I4: dropped redundant Affinity | K4: Yes | L4: =(D4*6)+(E4*4) | M4: Yes | O4: Yes | Q4: Yes
A5: Wandering Swordsman | B5: Unit | C5: 600 | D5: 60 | E5: 60 | F5: Anima | G5: 3 | H5: None | K5: Yes | L5: =(D5*6)+(E5*4) | M5: Yes | O5: Yes | Q5: Yes
A6: Huntress of Green Glade | B6: Unit | C6: 800 | D6: 50 | E6: 50 | F6: Anima | G6: 3 | H6: Immune to 0-cost traps | I6: wording polish | K6: Yes | L6: =(D6*6)+(E6*4) | M6: Yes | O6: Yes
A7: Fierce Gladiator | B7: Unit | C7: 1000 | D7: 70 | E7: 90 | F7: Anima | G7: 3 | H7: +500 Crystal on successful defend | K7: Yes | L7: =(D7*6)+(E7*4)
A8: Canyon Warg | B8: Unit | C8: 750 | D8: 70 | E8: 30 | F8: Nature | G8: 3 | H8: None | K8: Yes | L8: =(D8*6)+(E8*4) | M8: Yes | Q8: Yes
A9: Armored Bee | B9: Unit | C9: 480 | D9: 30 | E9: 0 | F9: Nature | G9: 2 | H9: +60 DEF until the end of that turn once | K9: Yes | L9: =(D9*6)+(E9*4) | M9: Yes | O9: Yes
A10: Armored Rhino | B10: Unit | C10: 720 | D10: 60 | E10: 85 | F10: Nature | G10: 3 | H10: None | K10: Yes | L10: =(D10*6)+(E10*4) | M10: Yes | P10: Yes
A11: Lightbringer | B11: Unit | C11: 1200 | D11: 80 | E11: 40 | F11: Divine | G11: 3 | H11: +100 DEF vs Chaos | I11: dropped redundant Affinity | K11: Yes | L11: =(D11*6)+(E11*4)
A12: Chaotic Wisp | B12: Unit | C12: 100 | D12: 20 | E12: 0 | F12: Chaos | G12: 1 | H12: None | K12: Yes | L12: =(D12*6)+(E12*4) | M12: Yes | O12: Yes
A13: Foul Wisp | B13: Unit | C13: 100 | D13: 0 | E13: 25 | F13: Chaos | G13: 1 | H13: None | K13: Yes | L13: =(D13*6)+(E13*4) | M13: Yes | O13: Yes
A14: Doom Wisp | B14: Unit | C14: 100 | D14: 15 | E14: 15 | F14: Chaos | G14: 1 | H14: None | K14: Yes | L14: =(D14*6)+(E14*4) | M14: Yes | O14: Yes
A15: Night Whisperer | B15: Unit | C15: 900 | D15: 30 | E15: 30 | F15: Chaos | G15: 3 | H15: +30 ATK and DEF for each exposed ‘wisp’ card on its side | I15: ATK&DEF→ATK and DEF | K15: Yes | L15: =(D15*6)+(E15*4) | M15: Yes | P15: Yes
A16: Leorudus the Warlord | B16: Unit | C16: 1150 | D16: 80 | E16: 80 | F16: Anima | G16: 5 | H16: +20 ATK and DEF for each other exposed Anima card on its side | I16: ATK&DEF→ATK and DEF | K16: Yes | L16: =(D16*6)+(E16*4) | M16: Yes | P16: Yes
A17: Aether Warden | B17: Unit | C17: 800 | D17: 30 | E17: 110 | F17: Divine | G17: 3 | H17: In Reckoning if it defends, attacker loses 300 Crystals | K17: Yes | L17: =(D17*6)+(E17*4)
A18: Void Stalker | B18: Unit | C18: 720 | D18: 65 | E18: 25 | F18: Chaos | G18: 3 | H18: +20 ATK if it attack an Exposed unit. | I18: wording polish | K18: Yes | L18: =(D18*6)+(E18*4) | M18: Yes | O18: Yes
A19: Swarmcaller | B19: Unit | C19: 950 | D19: 45 | E19: 45 | F19: Nature | G19: 4 | H19: +15 ATK and DEF for each other exposed Nature card on its side | I19: ATK&DEF→ATK and DEF | K19: Yes | L19: =(D19*6)+(E19*4) | M19: Yes | O19: Yes
A20: Ironclad Sentinel | B20: Unit | C20: 1100 | D20: 55 | E20: 95 | F20: Anima | G20: 5 | H20: Immune to 0-cost traps. Immune to Tech. | I20: Shortened immunity wording. | K20: Yes | L20: =(D20*6)+(E20*4)
A21: Tomb Bandit | B21: Unit | C21: 1000 | D21: 75 | E21: 60 | F21: Anima | G21: 4 | H21: Immune to traps. | I21: Shortened immunity wording. | K21: Yes | L21: =(D21*6)+(E21*4) | M21: Yes | Q21: Yes
A22: Scout Probe | B22: Unit | C22: 700 | D22: 40 | E22: 50 | F22: Cosmic | G22: 3 | H22: Choose and reveal any adjacent cell after it attacked. | I22: square→cell | K22: Yes | L22: =(D22*6)+(E22*4) | M22: Yes | O22: Yes | Q22: Yes
A23: Lab Zombie | B23: Unit | C23: 700 | D23: 55 | E23: 20 | F23: Bio | G23: 3 | H23: With Mutagen flag: +45 ATK vs Nature or Anima. | I23: wording polish | K23: Yes | L23: =(D23*6)+(E23*4) | M23: Yes | P23: Yes
A24: Lab Bloater | B24: Unit | C24: 800 | D24: 20 | E24: 85 | F24: Bio | G24: 4 | H24: With Mutagen flag: owner can destroy both units in Reckoning. Both players pay no Crystal cost. | I24: wording polish | K24: Yes | L24: =(D24*6)+(E24*4) | M24: Yes | P24: Yes | Q24: Yes
A25: Lab Crawler | B25: Unit | C25: 1200 | D25: 95 | E25: 60 | F25: Bio | G25: 5 | H25: With Mutagen flag: this card can target 3 cards | I25: wording polish | K25: Yes | L25: =(D25*6)+(E25*4) | M25: Yes | O25: Yes
A26: Pit Lord | B26: Unit | C26: 1250 | D26: 120 | E26: 100 | F26: Chaos | G26: 5 | H26: Destroy this card after Reckoning with Divine Unit. After this card attacked, halve its ATK and DEF permanently | I26: ATK&DEF→ATK and DEF | K26: Yes | L26: =(D26*6)+(E26*4) | M26: Yes | P26: Yes
A27: Ancient Lich | B27: Unit | C27: 750 | D27: 60 | E27: 60 | F27: Chaos | G27: 3 | H27: Immune to Tech. | I27: Shortened immunity wording. | K27: Yes | L27: =(D27*6)+(E27*4)
A28: Hyperspeed Saucer | B28: Unit | C28: 850 | D28: 80 | E28: 40 | F28: Cosmic | G28: 4 | H28: Permanently increase this card's ATK and DEF by 10 at the end of each of their turn | I28: ATK&DEF→ATK and DEF | K28: Yes | L28: =(D28*6)+(E28*4)
A29: Mountain Sage | B29: Unit | C29: 600 | D29: 50 | E29: 30 | F29: Arcane | G29: 3 | H29: Double effect of Tech card applied to this unit | K29: Yes | L29: =(D29*6)+(E29*4)
A30: War Genie | B30: Unit | C30: 1150 | D30: 100 | E30: 80 | F30: Arcane | G30: 4 | H30: -10 ATK permanently after it attacked | K30: Yes | L30: =(D30*6)+(E30*4) | M30: Yes | Q30: Yes
A31: Grand Wizard | B31: Unit | C31: 1100 | D31: 90 | E31: 70 | F31: Arcane | G31: 4 | H31: In Reckoning: flip a coin. Heads: +30 ATK and DEF until this turn’s end | I31: ATK&DEF→ATK and DEF; Head→Heads | K31: Yes | L31: =(D31*6)+(E31*4)
A32: Archbishop | B32: Unit | C32: 1200 | D32: 70 | E32: 90 | F32: Divine | G32: 4 | H32: If this card would be destroyed, the owner can destroy 1 other Divine card on their side instead | K32: Yes | L32: =(D32*6)+(E32*4) | M32: Yes | Q32: Yes
A33: Space Boy | B33: Unit | C33: 800 | D33: 75 | E33: 65 | F33: Cosmic | G33: 3 | H33: None | K33: Yes | L33: =(D33*6)+(E33*4) | M33: Yes | P33: Yes
A34: Slim Gray Trooper | B34: Unit | C34: 750 | D34: 45 | E34: 45 | F34: Cosmic | G34: 2 | H34: +30 ATK and DEF if 10 or more cells on its side is revealed | I34: ATK&DEF→ATK and DEF | K34: Yes | L34: =(D34*6)+(E34*4)
A35: Horn Face | B35: Unit | C35: 1350 | D35: 85 | E35: 60 | F35: Cosmic | G35: 5 | H35: After successfully attack, flip 3 coins. It can attack again equal to number of head. | K35: Yes | L35: =(D35*6)+(E35*4)
A36: Railgun Tank | B36: Unit | C36: 1500 | D36: 150 | E36: 95 | F36: Anima | G36: 5 | H36: After successfully attack, this card cannot attack on the next of their turn. | K36: Yes | L36: =(D36*6)+(E36*4)
A37: Lazy Troll | B37: Unit | C37: 1000 | D37: 120 | E37: 60 | F37: Nature | G37: 5 | H37: If this card performs an attack, flip a coin. Tails: it stops attacking. | I37: Tail→Tails | K37: Yes | L37: =(D37*6)+(E37*4) | M37: Yes | O37: Yes
A38: Leech Man | B38: Unit | C38: 880 | D38: 60 | E38: 40 | F38: Bio | G38: 4 | H38: +10 DEF permanently after it performed attack on unit. Also +10 ATK with mutagen flag | K38: Yes | L38: =(D38*6)+(E38*4) | M38: Yes | P38: Yes
A39: Immortal Vampire | B39: Unit | C39: 1200 | D39: 30 | E39: 80 | F39: Chaos | G39: 4 | H39: +50 ATK for each other exposed Chaos card on its side. In Reckoning with Divine, destroy this card. | K39: Yes | L39: =(D39*6)+(E39*4) | M39: Yes | O39: Yes | P39: Yes
A40: Vampire Servant | B40: Unit | C40: 800 | D40: 20 | E40: 20 | F40: Chaos | G40: 2 | H40: If a 'Vampire' card will be destroyed, destroy this card instead. Usable face-down. | K40: Yes | L40: =(D40*6)+(E40*4) | M40: Yes | P40: Yes
...

Sheet Union
A1: Table 1
A2: Card Name | B2: Card Type | C2: Cost | D2: ATK | E2: DEF | F2: Affinity | G2: Rarity | H2: Partial Ability | I2: Full Ability | J2: Comment | K2: Partial Formula | L2: Full Formula | M2: Union Zone | N2: Have illustration | O2: Demo | P2: Test 1
A3: Gryphon Rider | B3: Union | D3: 125 | E3: 90 | F3: Divine | H3: None | I3: None | K3: 1 ??? + 1 ??? + 1000 cost | L3: Gryphon + 1 Divine + 1000 cost | M3: 10000 01000 00100 00010 00001 | N3: Yes | O3: Yes
A4: Seraphim Fistmaster | B4: Union | D4: 120 | E4: 120 | F4: Divine | H4: Double ATK and DEF against ??? Affinity | I4: Double ATK and DEF against Chaos | J4: Partial: ATK&DEF→ATK and DEF; dropped redundant Affinity | Full: ATK&DEF→ATK and DEF | K4: 1 ??? + 1 ??? + 1500 cost | L4: 1 ‘Seraph’ unit + 1 Divine (≥ 800 cost) + 1500 cost | M4: 11011 10001 00000 10001 11011 | N4: Yes | O4: Yes
A5: Gaia Turtle | B5: Union | D5: 0 | E5: 205 | F5: Nature | H5: None | I5: None | K5: 2 ??? + 2000 cost | L5: 2 any units (≥90 DEF) + 2000 cost | M5: 00000 00000 01110 01110 00000 | N5: Yes | O5: Yes
A6: Barros the Colossal | B6: Union | D6: 150 | E6: 130 | F6: Nature | H6: None | I6: None | K6: 2 ???+ 1500 cost | L6: 2 Nature (≥ 800 cost) + 1500 cost | M6: 00000 01010 00100 01010 00000 | N6: Yes | O6: Yes
A7: X-Death Squad | B7: Union | D7: 50 | E7: 50 | F7: Anima | H7: In Reckoning, pay ???, destroy foe’s unit. They pay ???. | I7: In Reckoning: pay 1000, destroy foe’s unit. They pay no Crystal cost. | J7: Full: wording polish | K7: 1 ??? + 2 ??? + 800 cost | L7: 1 Anima (≥ 800 cost) + 2 Anima + 800 cost | M7: 10101 00000 10101 00000 10101 | N7: Yes | O7: Yes
A8: Rocket Marauder | B8: Union | D8: 125 | E8: 105 | F8: Bio | H8: None | I8: None | K8: 1 ??? + 1 ??? + 1000 cost | L8: 1 Bio (≥ 800 cost) + 1 Anima (≥ 800 cost) + 1000 cost | M8: 00000 00000 00000 01010 10101 | N8: Yes | O8: Yes
A9: Lord of Terror | B9: Union | D9: 150 | E9: 100 | F9: Chaos | H9: -50 ATK if ??? | I9: -50 ATK if attacks Dead End | K9: 2 ??? + 1500 cost | L9: 2 Chaos (≥ 800 cost) + 1500 cost | M9: 00000 00100 00100 01110 00100 | N9: Yes | O9: Yes
A10: Armored Dino | B10: Union | D10: 95 | E10: 60 | F10: Nature | H10: In Reckoning, pay ??? Crystal cost to +??DEF | I10: In Reckoning: pay 1000 Crystal cost to +60 DEF | J10: Full: wording polish | K10: 1 ??? + 1 ??? + 700 cost | L10: 1 Armored Nature card + 1 Nature (≥ 700 cost) + 800 cost | M10: 00000 01110 11111 00000 00000 | N10: Yes | O10: Yes
A11: Greater Succubus | B11: Union | D11: 30 | E11: 50 | F11: Chaos | H11: Once, after Reckoning: +ATK and DEF equal to ??? | I11: Once: after Reckoning: +ATK and DEF equal to half of that foe’s card | J11: Partial: ATK&DEF→ATK and DEF | Full: ATK&DEF→ATK and DEF | K11: 1 ??? + 1 ??? + 800 cost | L11: 1 Succubus + 1 Chaos + 800 cost | M11: 00100 11111 10001 00000 00000 | N11: Yes | O11: Yes
A12: Pixie Queen | B12: Union | D12: 30 | E12: 30 | F12: Divine | H12: +5 ATK for each ???? | I12: +5 ATK for each Divine cards on its side | K12: 1 ??? + 1 ??? + 300 cost | L12: 1 Tiny Pixie + 1 Divine+ 300 cost | M12: 00100 00100 10001 10101 01010 | N12: Yes | O12: Yes
A13: Diamond Unicorn | B13: Union | D13: 30 | E13: 35 | F13: Divine | H13: Once Union, ??? until this turn’s end | I13: Once Union, +15 ATK until this turn’s end | K13: 1 ??? + 1 ??? + 500 cost | L13: 1 Ponycorn + 1 Divine card + 500 cost | M13: 00100 01010 10001 01010 00100 | N13: Yes | O13: Yes
A14: Choir Lead Amber | B14: Union | D14: 35 | E14: 35 | F14: Divine | H14: +20 ATK to all ????? | I14: +20 ATK to all Divine units on its side | K14: 3 ??? + 500 cost | L14: 3 Choir Lady cards + 500 cost | M14: 01100 01011 01001 11000 11000 | N14: Yes | O14: Yes
A15: Raijin and Fujin | B15: Union | D15: 80 | E15: 80 | F15: Divine | H15: None | I15: None | K15: 1 ??? + 1 ??? + 800 cost | L15: Raijin + Fujin + 800 cost | M15: 10001 10001 10001 10001 10001 | N15: Yes | O15: Yes
A16: Sky Protector | B16: Union | D16: 0 | E16: 0 | F16: Divine | H16: If this card defends, DEF becomes ???, ATK becomes ???. If this card performs attack, ATK becomes ???, DEF becomes ???. | I16: If this card defends, DEF becomes 60, ATK becomes 0. If this card performs attack, ATK becomes 60, DEF becomes 0. | K16: 1 ??? + 1 ??? + 400 cost | L16: Sunrise Lady + Moonrise Gentleman + 400 cost | M16: 11111 00000 00000 00000 00000 | N16: Yes | O16: Yes
A17: Giant Mining Pod | B17: Union | D17: 20 | E17: 80 | F17: Cosmic | H17: If this card attacks a Dead End, receive ???Crystals | I17: If this card attacks a Dead End, receive 200 Crystals | K17: 1 ??? + 1 ??? + 500 cost | L17: 1 Miner probe + 1 Cosmic + 500 cost | M17: 11111 01110 01110 00100 00000 | N17: Yes | O17: Yes
A18: Kitsune | B18: Union | D18: 35 | E18: 35 | F18: Chaos | H18: None | I18: None | K18: 1 ??? + 1 ??? + 300 cost | L18: Dark Monk + 1 Chaos + 300 cost | M18: 01100 00110 01100 00110 01100 | N18: Yes | O18: Yes
A19: Ten Arms Yaksa | B19: Union | D19: 45 | E19: 30 | F19: Chaos | H19: This card can choose ?? attack targets. -?? ATK for each successful attack. | I19: This card can choose two attack targets. -5 ATK for each successful attack. | K19: 1 ??? + 1 ??? + 600 cost | L19: Yaksa + 1 Chaos + 600 cost | M19: 11011 00100 00100 01110 01010 | N19: Yes | O19: Yes
A20: Skeleton Overlord | B20: Union | D20: 50 | E20: 5 | F20: Chaos | H20: None | I20: None | K20: 3 ??? + 400 cost | L20: 3 Skeleton cards + 400 cost | M20: 01110 00000 11111 00000 01110 | N20: Yes | O20: Yes
A21: Katana Shark | B21: Union | D21: 75 | E21: 50 | F21: Nature | H21: None | I21: None | K21: 3 ??? + 800 cost | L21: 3 ‘Sharks’ name + 800 cost | M21: 11000 00100 00010 00010 00001 | N21: Yes | O21: Yes
A22: Rocket Peacock | B22: Union | D22: 150 | E22: 100 | F22: Nature | H22: After this card battles, select 1 foe’s card, flip a coin. Head: ??? | I22: After this card battles, select 1 foe’s card, flip a coin. Heads: destroy that card | J22: Full: Head→Heads | K22: 1 ??? + 1 ??? + 1500 cost | L22: Ostrich Cannon + 1 Nature + 1500 cost | M22: 10001 10001 10001 00000 00100 | N22: Yes | O22: Yes
A23: Scarlet Shroom | B23: Union | D23: 0 | E23: 80 | F23: Nature | H23: If ???, put venom flag on all ???. | I23: Once Union, put venom flag on all foe’s Exposed unit | J23: Full: wording polish | K23: 2 ??? + 500 cost | L23: 2 Nature cards + 500 cost | M23: 11111 00100 00100 00100 00000 | N23: Yes | O23: Yes
A24: Ancient Lizard | B24: Union | D24: 75 | E24: 75 | F24: Nature | H24: None | I24: None | K24: 1 ??? + 1 ???+ 800 cost | L24: 1 Flame Lizard + 1 Nature + 800 cost | M24: 00000 00100 01110 00100 00000 | N24: Yes | O24: Yes
A25: Burning Phoenix | B25: Union | D25: 125 | E25: 50 | F25: Arcane | H25: Cannot be destroyed by ???. If targeted by tech, ??? | I25: Cannot be destroyed by non-union cards. If targeted by Tech, destroy this card. | J25: Full: wording polish | K25: 1 ??? + 1 ??? + 1 ??? + 800 cost | L25: 1 Arcane (≥ 500 cost) + 1 Nature (≥ 500 cost) + 1 Divine (≥ 500 cost) + 800 cost | M25: 00100 01110 10101 00000 00000 | N25: Yes | O25: Yes
A26: Berserk Hyena | B26: Union | D26: 40 | E26: 0 | F26: Nature | H26: None | I26: None | K26: 2 ???+ 500 cost | L26: 2 Nature + 500 cost | M26: 00000 11111 10101 10101 00000 | N26: Yes | O26: Yes
A27: False Prophet | B27: Union | D27: 20 | E27: 40 | F27: Divine | H27: At their turn’s end: Reveal ???. If it was a Dead End, destroy this card. Otherwise, gain ??? | I27: At their turn’s end: Reveal 1 foe’s cell. If it was a Dead End, destroy this card. Otherwise, gain 600 Crystals. | J27: Full: wording polish | K27: 2 ??? + 300 cost | L27: 2 Divine cards + 300 cost | M27: 00100 01010 00100 00000 00000 | N27: Yes | O27: Yes
A28: Colorful Mage | B28: Union | D28: 40 | E28: 40 | F28: Arcane | H28: Foe’s non-Arcane get ??? in Reckoning with this card | I28: Foe’s non-Arcane get -10 ATK and DEF permanently in Reckoning with this card | J28: Full: ATK&DEF→ATK and DEF | K28: ??? + ???+ ??? + 500 cost | L28: Red Mage + Green Mage + Blue Mage + 500 cost | M28: 00001 00010 01100 01100 10000 | N28: Yes | O28: Yes
A29: Grand Fort Captain | B29: Union | D29: 45 | E29: 40 | F29: Anima | H29: None | I29: None | K29: 2 ??? + 500 cost | L29: 2 Grand Fort card + 500 cost | M29: 00000 00100 01110 00100 00000 | N29: Yes | O29: Yes
A30: Volatile Slasher | B30: Union | D30: 50 | E30: 45 | F30: Bio | H30: Once, after Reckoning with non-Bio, it gain ???. | I30: Once: after Reckoning with non-Bio, it gain +50 ATK permanently. | J30: Full: wording polish | K30: 1 ??? + 1 ??? + 1000 cost | L30: 1 Bladeshifter + 1 Bio card + 1000 cost | M30: 10000 01100 01100 01100 10000 | N30: Yes | O30: Yes
A31: Moon Tribe Shaman | B31: Union | D31: 25 | E31: 55 | F31: Cosmic | H31: Upon union, revive 1 ???. Double its cost. | I31: Upon union, revive 1 Moon non-Union card. Double its cost. | K31: 1 ??? + 1 ??? + 500 cost | L31: 1 Moon card+ 1 Cosmic card + 500 cost | M31: 10001 01010 00100 00100 00100 | N31: Yes | O31: Yes
A32: Rebel King | B32: Union | D32: 60 | E32: 40 | F32: Anima | H32: At the end of foe’s turn: ??? and swap its ATK and DEF | I32: At the end of foe’s turn: the owner of this card select 1 Exposed foe’s unit and swap its ATK and DEF | J32: Partial: ATK&DEF→ATK and DEF | Full: ATK&DEF→ATK and DEF | K32: ??? + ??? + 800 cost | L32: Jirayu the Rebellious Prince + 1 Anima card (≥ 500 cost) + 800 cost | M32: 00100 00000 10101 00100 00100 | N32: Yes | O32: Yes
A33: Kiba the Giant Slayer | B33: Union | D33: 80 | E33: 55 | F33: Anima | H33: +??? vs Union | I33: +30 ATK vs Union | K33: ??? + ??? + 1000 cost | L33: Kiyoko the Death Whisper + Silver Spearman + 1000 cost | M33: 01010 01010 01010 01010 01010 | N33: Yes | O33: Yes
A34: Moon Lady Ninja | B34: Union | D34: 65 | E34: 50 | F34: Anima | H34: Once, this card is ???. | I34: Once: this card is not destroyed. | J34: Full: wording polish | K34: ??? + ??? + 800 cost | L34: Kiyoko the Death Whisper + 1 Anima card + 800 cost | M34: 00100 00100 01110 00100 00100 | N34: Yes | O34: Yes
A35: Imperial Frame | B35: Union | D35: 45 | E35: 30 | F35: Cosmic | H35: None | I35: None | K35: ??? + ??? + 500 cost | L35: Laser Walker + 1 Cosmic card + 500 cost | M35: 00111 00001 10001 10000 11100 | N35: Yes | O35: Yes
A36: Giant Meteor Vergaia | B36: Union | D36: 60 | E36: 0 | F36: Cosmic | H36: Destroy it at turn's end, then destroy all ??? | I36: Destroy it at turn's end, then destroy all Exposed foe’s units surrounding the card that this card attacked. | J36: Full: wording polish | K36: ??? + ??? + 1000 cost | L36: Striker Comet + 2 Cosmic card + 1000 cost | M36: 10000 01000 00000 00111 00111 | N36: Yes | O36: Yes
A37: Blood-hungry Mutant | B37: Union | D37: 55 | E37: 40 | F37: Cosmic | H37: After destroying foe’s card: ??? | I37: After destroying foe’s card: +80 Crystals | K37: 2 ??? + 600 cost | L37: 2 Mutant cards + 600 cost | M37: 00000 01010 10101 01010 00000 | N37: Yes | O37: Yes
A38: Gamma Mermaid | B38: Union | D38: 30 | E38: 20 | F38: Bio | H38: Non-Bio defender get ???. With Mutagen Flag: +20 ??? | I38: Non-Bio defender get -20 DEF. With Mutagen flag: +20 ATK and DEF to all ally Bio units | J38: Full: ATK&DEF→ATK and DEF | K38: ??? + ??? + 1000 cost | L38: 1 Gamma cards + 1 Bio card + 500 cost | M38: 00000 01110 01010 01110 00000 | N38: Yes | O38: Yes
A39: Tendrill Tyrant | B39: Union | D39: 90 | E39: 110 | F39: Bio | H39: Can attack ? times per turn | I39: Can attack 3 times per turn | K39: 1 ??? + 2 ??? + 1500 cost | L39: 1 Bio with mutagen flag + 2 Bio (≥ 800 cost) + 1500 cost | M39: 00100 00100 11111 00100 00100
A40: Helios the Prideful Fortress | B40: Union | D40: 145 | E40: 100 | F40: Cosmic | H40: As long as there is exposed ???, this card cannot be ??? | I40: With another exposed Cosmic: this card cannot be destroyed | K40: 2 ??? + 1500 cost | L40: 2 Cosmic (≥ 800 cost) + 1500 cost | M40: 00100 01010 10001 01010 00100
...

Sheet Trap
A1: Table 1
A2: Card Name | B2: Card Type | C2: Cost | D2: ATK | E2: DEF | F2: Affinity | G2: Rarity | H2: Ability | I2: Comment | J2: Formula | K2: Have illustration | L2: Suggested cost | M2: Demo | N2: Test 1 | O2: ="Booster Pack - Blightsilver / "&COUNTIF(N3:N545,"Yes") | P2: ="Booster Pack - Unseen Presence / "&COUNTIF(O3:O545,"Yes") | Q2: ="Booster Pack - Wind of Dominance / "&COUNTIF(P3:P545,"Yes")
A3: Trap Hole | B3: Trap | C3: 0 | G3: 1 | H3: Flip 3 coins. Attacker loses 20 Crystals per Head. | I3: Grammar: coins plural; per Head wording. | K3: Yes | M3: Yes | O3: Yes
A4: Hostage | B4: Trap | C4: 200 | G4: 2 | H4: The trapper reveals 1 own cell. This turn: attacker cannot target that cell. | I4: wording polish | K4: Yes | M4: Yes | O4: Yes
A5: Bait | B5: Trap | C5: 0 | G5: 1 | H5: The trapper chooses one other cell on their field and reveal it | I5: wording polish | K5: Yes | M5: Yes | O5: Yes
A6: Blackmail | B6: Trap | C6: 0 | G6: 2 | H6: The attacker choose either discarding 1 Tech Card or end the turn immediately | K6: Yes | M6: Yes | O6: Yes
A7: Cursed Reflection | B7: Trap | C7: 500 | G7: 3 | H7: Swap the attacker's ATK and DEF until the trapper’s turn ends | I7: ATK&DEF→ATK and DEF | K7: Yes | M7: Yes | P7: Yes
A8: Explosive Barrels | B8: Trap | C8: 0 | G8: 5 | H8: Destroy the attacking unit. Trapper also pay the same cost as attacker. | K8: Yes | M8: Yes | Q8: Yes
A9: Hypnosis | B9: Trap | C9: 800 | G9: 4 | H9: The attacking unit cannot attack during their next turn | K9: Yes | M9: Yes | O9: Yes
A10: Flame Trap | B10: Trap | C10: 250 | G10: 2 | H10: Attacking unit get -10 ATK permanently | K10: Yes | M10: Yes | P10: Yes
A11: Echo Barrier | B11: Trap | C11: 1000 | G11: 3 | H11: This turn, attacker cannot perform any more attack. | K11: Yes | M11: Yes | P11: Yes
A12: Mana Drain | B12: Trap | C12: 200 | G12: 2 | H12: Attacking player loses 300 Crystals. Increase trapper’s Crystal by that amount | K12: Yes
A13: Defensive Pheromone | B13: Trap | C13: 500 | G13: 3 | H13: The trapper swaps 1 'Armored' Nature card on their side with this cell, then repeat Reckoning. | I13: wording polish | K13: Yes | M13: Yes | P13: Yes
A14: Spike Trap | B14: Trap | C14: 1500 | G14: 5 | H14: Destroy the attacking unit | K14: Yes | M14: Yes | Q14: Yes
A15: Snare Trap | B15: Trap | C15: 500 | G15: 4 | H15: The attacking unit's ability becomes None until attacker’s next turn ends | K15: Yes | M15: Yes | Q15: Yes
A16: Brainwash | B16: Trap | C16: 1500 | G16: 5 | H16: The attacker chooses their own ally as an attack target | I16: wording polish | K16: Yes | M16: Yes | P16: Yes
A17: Bunker | B17: Trap | C17: 600 | G17: 4 | H17: Attacker cannot target surrounding cells until the end of this turn. | K17: Yes | M17: Yes | Q17: Yes
A18: Foul Gas | B18: Trap | C18: 0 | G18: 3 | H18: -5 ATK to all the attacking player’s units until the end of this turn | K18: Yes | M18: Yes | O18: Yes
A19: Choking Gas | B19: Trap | C19: 800 | G19: 4 | H19: -20 ATK to all the attacking player’s units until the end of this turn | K19: Yes
A20: Potent Poison | B20: Trap | C20: 600 | G20: 4 | H20: Attacking unit permanently lose 5 ATK and DEF. It lose more 5 ATK and DEF for each trap cards in trapper’s void | I20: ATK&DEF→ATK and DEF | K20: Yes
A21: Acid Trap Hole | B21: Trap | C21: 0 | G21: 1 | H21: Flip 2 coins. Attacker loses 50 Crystals per Head. | I21: Grammar: coins plural; per Head wording. | K21: Yes | M21: Yes | O21: Yes
A22: Lava Trap Hole | B22: Trap | C22: 50 | G22: 2 | H22: Flip 3 coins. Attacker loses 100 Crystals per Head. | I22: Grammar: coins plural; per Head wording. | K22: Yes
A23: Fissure | B23: Trap | C23: 100 | G23: 3 | H23: Attacking player loses 200 Crystals | K23: Yes
A24: Soul Blast | B24: Trap | C24: 1000 | G24: 5 | H24: Attacking player lose 150 Crystals for each unit cards in trapper’s void | K24: Yes
A25: Grudge | B25: Trap | C25: 850 | G25: 2 | H25: -10 ATK to the attacking monster permanently for each unit cards in trapper’s void | K25: Yes
A26: Anti-virus | B26: Trap | C26: 600 | G26: 1 | H26: If attacker is Bio, flip a coin. Heads: destroy it. Always Heads, if trapper’s Crystal is 1000 or less. | I26: Head→Heads | K26: Yes
A27: Witch Hunt | B27: Trap | C27: 600 | G27: 1 | H27: If attacker is Arcane, flip a coin. Heads: destroy it. Always Heads, if trapper’s Crystal is 1000 or less. | I27: Head→Heads | K27: Yes
A28: Standoff | B28: Trap | C28: 600 | G28: 1 | H28: If attacker is Anima, flip a coin. Heads: destroy it. Always Heads, if trapper’s Crystal is 1000 or less. | I28: Head→Heads | K28: Yes
A29: Apple of Adam | B29: Trap | C29: 600 | G29: 1 | H29: If attacker is Divine, flip a coin. Heads: destroy it. Always Heads, if trapper’s Crystal is 1000 or less. | I29: Head→Heads | K29: Yes
A30: Purify | B30: Trap | C30: 600 | G30: 1 | H30: If attacker is Chaos, flip a coin. Heads: destroy it. Always Heads, if trapper’s Crystal is 1000 or less. | I30: Head→Heads | K30: Yes
A31: Solar Flare | B31: Trap | C31: 600 | G31: 1 | H31: If attacker is Cosmic, flip a coin. Heads: destroy it. Always Heads, if trapper’s Crystal is 1000 or less. | I31: Head→Heads | K31: Yes
A32: Hunting Season | B32: Trap | C32: 600 | G32: 1 | H32: If attacker is Nature, flip a coin. Heads: destroy it. Always Heads, if trapper’s Crystal is 1000 or less. | I32: Head→Heads | K32: Yes
A33: Dart Trap | B33: Trap | C33: 300 | G33: 2 | H33: If the attacking monster is the first one in that turn, destroy it. | K33: Yes
A34: Science Cage | B34: Trap | C34: 800 | G34: 3 | H34: If attacking unit Is Bio affinity, end their turn immediately. Remove all flags from it. | K34: Yes
A35: Loop Hole | B35: Trap | C35: 800 | G35: 3 | H35: If attacker is Arcane, end the their turn immediately. | K35: Yes
A36: Talisman of Light | B36: Trap | C36: 800 | G36: 3 | H36: If attacker is Chaos, -50 ATK to that monster permanently | K36: Yes
A37: Forbidden Grail | B37: Trap | C37: 800 | G37: 3 | H37: If attacker is Divine, -50 DEF to that monster permanently | K37: Yes
A38: Electric Fence | B38: Trap | C38: 800 | G38: 3 | H38: If attacker is Nature, it cannot attack until attacker’s next turn ends | K38: Yes
A39: Discourage | B39: Trap | C39: 800 | G39: 3 | H39: If attacker Is Anima -15 ATK to all Exposed units on their field until attacker’s next turn ends | I39: wording polish | K39: Yes
A40: Galaxy Toll | B40: Trap | C40: 800 | G40: 3 | H40: If attacker is Cosmic, foe loses 1000 Crystals | I40: wording polish | K40: Yes
...

Sheet Tech
A1: Table 1
A2: Card Name | B2: Card Type | C2: Cost | D2: ATK | E2: DEF | F2: Affinity | G2: Rarity | H2: Ability | I2: Comment | J2: Formula | K2: Illustration | L2: Suggested cost | M2: Demo | N2: Test 1 | O2: ="Booster Pack - Blightsilver / "&COUNTIF(N3:N556,"Yes") | P2: ="Booster Pack - Unseen Presence / "&COUNTIF(O3:O556,"Yes") | Q2: ="Booster Pack - Wind of Dominance / "&COUNTIF(P3:P556,"Yes")
A3: Welcoming Door | B3: Tech | C3: 0 | G3: 1 | H3: Reveal any own cell. | I3: Shortened; cell terminology. | K3: Yes
A4: Spy | B4: Tech | C4: 0 | G4: 1 | H4: Reveal 1 of foe’s cell | K4: Yes | M4: Yes | O4: Yes
A5: Ceasefire | B5: Tech | C5: 0 | G5: 3 | H5: Both players skip 1 turn (tax is forced to apply) | K5: Yes
A6: Make Friend | B6: Tech | C6: 0 | G6: 5 | H6: Both players select 1 monster from their field. Those monster cannot attack until this player’s next turn ends | K6: Yes
A7: Double Spy | B7: Tech | C7: 0 | G7: 2 | H7: Only trigger if this player have Spy card in the void. Reveal 2 cell on foe's side of the field. | I7: square→cell | K7: Yes
A8: Invisible Spy | B8: Tech | C8: 0 | G8: 3 | H8: Only trigger if this player have Double Spy card in the void. Reveal 2 cell on foe's side of the field. | I8: square→cell | K8: Yes
A9: Corrupted Spy | B9: Tech | C9: 0 | G9: 4 | H9: Reveal 3 foe cells. Pay 700 Crystal cost per trap or unit found. | I9: Shortened; cell/Crystal cost. | K9: Yes
A10: Tease | B10: Tech | C10: 0 | G10: 2 | H10: Foe choose and reveal 1 of their cell | K10: Yes | M10: Yes | P10: Yes
A11: Bribe | B11: Tech | C11: 0 | G11: 3 | H11: Foe can choose to reveal a unit card and receive 700 Crystals or do nothing | K11: Yes | M11: Yes | O11: Yes
A12: Release Mutagen | B12: Tech | C12: 0 | G12: 4 | H12: Add Mutagen flag to 1 of this player’s unit | I12: wording polish | K12: Yes | M12: Yes | P12: Yes
A13: Prayer | B13: Tech | C13: 0 | G13: 4 | H13: Once: until foe’s turn ends: prevent Divine card from being destroyed | I13: wording polish | K13: Yes | M13: Yes | P13: Yes
A14: Arcane Nova | B14: Tech | C14: 3000 | G14: 5 | H14: Destroy up to 3 Exposed foe units (no cost is paid). This player discard all of their Tech cards afterward. | I14: wording polish | K14: Yes
A15: Rift Strike | B15: Tech | C15: 2000 | G15: 3 | H15: Choose 1 Exposed foe unit. Destroy other Exposed units in its row. Foe pays no Crystal cost. | I15: Shortened; Exposed/cell/Crystal cost. | K15: Yes
A16: Great Diplomacy | B16: Tech | C16: 1000 | G16: 4 | H16: Select up to 5 of their units and reveal them. | I16: wording polish | K16: Yes | M16: Yes | Q16: Yes
A17: War Supply | B17: Tech | C17: 1000 | G17: 3 | H17: This player’s units get +10 ATK and DEF in Reckoning until turn’s end | I17: ATK&DEF→ATK and DEF | K17: Yes | M17: Yes | O17: Yes
A18: Harsh Training | B18: Tech | C18: 500 | G18: 2 | H18: +10 ATK permanently to one of this player's unit. | K18: Yes
A19: Illegal Steroid | B19: Tech | C19: 1000 | G19: 4 | H19: +30 ATK for 1 unit until the end of this turn. | K19: Yes
A20: Secret Dagger | B20: Tech | C20: 600 | G20: 3 | H20: Can only be used on face-down unit. Turn that card exposed and +15 ATK until the end of this turn. | I20: wording polish | K20: Yes
A21: Garrison | B21: Tech | C21: 1500 | G21: 4 | H21: Until foe's turn ends: +20 DEF to all this player's cards in Reckoning | K21: Yes
A22: Bulletproof Vest | B22: Tech | C22: 850 | G22: 3 | H22: +15 DEF permanently for 1 Exposed unit. If use on face-down unit, flip it up. | I22: wording polish | K22: Yes
A23: Siege Cannon | B23: Tech | C23: 1000 | G23: 5 | H23: This turn: once, foe’s defending unit is destroyed. | I23: shortened | K23: Yes | M23: Yes | Q23: Yes
A24: Silence Agent | B24: Tech | C24: 2000 | G24: 4 | H24: Destroy 1 of foe’s Exposed unit | I24: wording polish | K24: Yes
A25: Accident | B25: Tech | C25: 1000 | G25: 3 | H25: Destroy 1 Exposed foe unit. If none, foe chooses 1 to Expose. Foe pays no Crystal cost. | I25: Shortened; Exposed terminology. | K25: Yes | M25: Yes | Q25: Yes
A26: Berserk | B26: Tech | C26: 2000 | G26: 5 | H26: Choose 1 Exposed ally. It gets 1 extra attack but is your only attacker this turn. Cannot use if you already attacked. | I26: Shortened; Exposed terminology. | K26: Yes
A27: Radar | B27: Tech | C27: 600 | G27: 1 | H27: Reveal 3 of foe’s cell | K27: Yes | M27: Yes | O27: Yes
A28: Palace Party | B28: Tech | C28: 500 | G28: 2 | H28: This player reveal 1 face-down unit. Foe must reveal 1 of their face-down unit (if any) | K28: Yes
A29: Essence Transfer | B29: Tech | C29: 700 | G29: 5 | H29: Choose 1 unit. Move all its ATK and DEF bonuses or debuffs to another ally unit. | I29: ATK&DEF→ATK and DEF | K29: Yes
A30: Blood Ritual | B30: Tech | C30: 1200 | G30: 4 | H30: Destroy 1 own card (no Crystal cost). Choose 1 Exposed foe unit; its ATK and DEF become 0 permanently. | I30: Fixed 'the this'; terminology. | K30: Yes
A31: Arcane Duplication | B31: Tech | C31: 1000 | G31: 5 | H31: Choose 1 unit. Create a token copy on an empty cell. Destroy the token at end of your next turn. | I31: Removed dangling 'This player.'; shortened. | K31: Yes
A32: Time Travel | B32: Tech | C32: 1800 | G32: 5 | H32: Once only, revive 1 unit to any unoccupied or empty cell in Exposed position. Double its Crystal cost. | I32: wording polish | K32: Yes
A33: Resurrection | B33: Tech | C33: 1500 | G33: 4 | H33: Once: revive 1 unit. It has no ATK,DEF, or ability. | I33: wording polish | K33: Yes | M33: Yes | Q33: Yes
A34: Tech Copy | B34: Tech | C34: 1000 | G34: 3 | H34: Foe show 1 Tech card in their hand. Add a copy of that card into this player's Tech Stack. | I34: wording polish
A35: Force Shield | B35: Tech | C35: 600 | G35: 2 | H35: Select 1card. It is not destroyed until the end of foe's turn | I35: wording polish
A36: Wisp Light | B36: Tech | C36: 250 | G36: 3 | H36: Destroy as many ally ‘wisp’ units. Reveal that much cells on foe's field.
A37: Lucky Day | B37: Tech | C37: 300 | G37: 2 | H37: Flip a coin. Heads: receive 600 Crystals. Always Heads, if trapper’s Crystal is 1000 or less. | I37: Head→Heads
A38: Immortal Blood | B38: Tech | C38: 1000 | G38: 3 | H38: Revive 1 immortal vampire or vampire servant.
A39: Yin Yang Swap | B39: Tech | C39: 1200 | G39: 4 | H39: Swap ATK and DEF on 1 Exposed unit until the end of this turn | I39: ATK&DEF→ATK and DEF
A40: Coin on the Street | B40: Tech | C40: 0 | G40: 1 | H40: Receive 20 Crystals
...

Sheet Count
A1: Table 1
A2: Rarity | B2: Expected | C2: Percentage of Pool | D2: Notes | E2: Actual
A3: Common | B3: 52 | C3: 0.347 | D3: Filler / staple cards | E3: =_xlfn.COUNTIFS('Unit'!$L$3:$L$568,"Yes",'Unit'!$G$3:$G$568,1)+_xlfn.COUNTIFS('Trap'!$L$3:$L$545,"Yes",'Trap'!$G$3:$G$545,1)+_xlfn.COUNTIFS('Tech'!$L$3:$L$556,"Yes",'Tech'!$G$3:$G$556,1)
A4: Uncommon | B4: 48 | C4: 0.337 | D4: - | E4: =_xlfn.COUNTIFS('Unit'!$L$3:$L$568,"Yes",'Unit'!$G$3:$G$568,2)+_xlfn.COUNTIFS('Trap'!$L$3:$L$545,"Yes",'Trap'!$G$3:$G$545,2)+_xlfn.COUNTIFS('Tech'!$L$3:$L$556,"Yes",'Tech'!$G$3:$G$556,2)
A5: Rare | B5: 27 | C5: 0.167 | D5: - | E5: =_xlfn.COUNTIFS('Unit'!$L$3:$L$568,"Yes",'Unit'!$G$3:$G$568,3)+_xlfn.COUNTIFS('Trap'!$L$3:$L$545,"Yes",'Trap'!$G$3:$G$545,3)+_xlfn.COUNTIFS('Tech'!$L$3:$L$556,"Yes",'Tech'!$G$3:$G$556,3)
A6: Legendary | B6: 16 | C6: 0.1 | D6: Strong but not broken | E6: =_xlfn.COUNTIFS('Unit'!$L$3:$L$568,"Yes",'Unit'!$G$3:$G$568,4)+_xlfn.COUNTIFS('Trap'!$L$3:$L$545,"Yes",'Trap'!$G$3:$G$545,4)+_xlfn.COUNTIFS('Tech'!$L$3:$L$556,"Yes",'Tech'!$G$3:$G$556,4)
A7: Exotic | B7: 9 | C7: 0.053 | D7: Very desirable | E7: =_xlfn.COUNTIFS('Unit'!$L$3:$L$568,"Yes",'Unit'!$G$3:$G$568,5)+_xlfn.COUNTIFS('Trap'!$L$3:$L$545,"Yes",'Trap'!$G$3:$G$545,5)+_xlfn.COUNTIFS('Tech'!$L$3:$L$556,"Yes",'Tech'!$G$3:$G$556,5)
A11: Rarity | B11: Expected | E11: Actual
A12: Blightsilver | B12: 60 | E12: =_xlfn.COUNTIFS('Unit'!$N$3:$N$568,"Yes")+_xlfn.COUNTIFS('Trap'!$N$3:$N$545,"Yes")+_xlfn.COUNTIFS('Tech'!$N$3:$N$556,"Yes")
A13: Unseen Presence | B13: 60 | E13: =_xlfn.COUNTIFS('Unit'!$O$3:$O$568,"Yes")+_xlfn.COUNTIFS('Trap'!$O$3:$O$545,"Yes")+_xlfn.COUNTIFS('Tech'!$O$3:$O$556,"Yes")
A14: Wind of Dominance | B14: 60 | E14: =_xlfn.COUNTIFS('Unit'!$P$3:$P$568,"Yes")+_xlfn.COUNTIFS('Trap'!$P$3:$P$545,"Yes")+_xlfn.COUNTIFS('Tech'!$P$3:$P$556,"Yes")

Sheet Rule
A1: Table 1
B2: Old | C2: New
A3: 1 | B3: Foe | C3: foe
A4: 2 | B4: Battle calculation | C4: Reckoning
A5: 3 | B5: Cannot attack | C5: wait
A6: 4 | B6: ATK&DEF | C6: ATK&DEF
A7: 5 | B7: If head | C7: Head:
A8: 6 | B8: If tail | C8: Tail:
A9: 7 | B9: Square, grid | C9: cell
A10: 8 | B10: exposed | C10: Exposed
