Workbook

Sheet Affinity
A1: Table 1
A2: Affinity | B2: Key strength
A3: Divine | B3: High defense, Anti-Chaos bonus
A4: Chaos | B4: High cost, powerful units, Especially weak to Divine
A5: Arcane | B5: Spending a lot of Crystal to maximize power in short time. A glass cannon.
A6: Nature | B6: Balanced
A7: Bio | B7: Few unit, mutate to other or attack a lot of times, Tech heavy
A8: Cosmic | B8: High discovery capacity, Tech heavy
A9: Anima | B9: Low cost, swarming

Sheet Unit
A1: Table 1
A2: Card Name | B2: Card Type | C2: Cost | D2: ATK | E2: DEF | F2: Affinity | G2: Rarity | H2: Ability | I2: Formula | J2: Have illustration | K2: Suggested cost | L2: Demo | M2: Test 1 | N2: ="Booster Pack - Blightsilver / "&COUNTIF(N3:N599,"Yes") -> Booster Pack - Blightsilver / 49 | O2: ="Booster Pack - Unseen Presence / "&COUNTIF(O3:O599,"Yes") -> Booster Pack - Unseen Presence / 50 | P2: ="Booster Pack - Wind of Dominance / "&COUNTIF(P3:P599,"Yes") -> Booster Pack - Wind of Dominance / 50
A3: Pyromancer | B3: Unit | C3: 900 | D3: 80 | E3: 0 | F3: Arcane | G3: 4 | H3: +30 ATK vs Nature Affinity | J3: Yes | K3: =(D3*6)+(E3*4) -> 480 | L3: Yes | P3: Yes
A4: Angel Gatekeeper | B4: Unit | C4: 1000 | D4: 40 | E4: 90 | F4: Divine | G4: 4 | H4: +50 ATK vs Chaos Affinity | J4: Yes | K4: =(D4*6)+(E4*4) -> 600 | L4: Yes | N4: Yes | P4: Yes
A5: Wandering Swordsman | B5: Unit | C5: 600 | D5: 60 | E5: 60 | F5: Anima | G5: 3 | H5: None | J5: Yes | K5: =(D5*6)+(E5*4) -> 600 | L5: Yes | N5: Yes | P5: Yes
A6: Huntress of Green Glade | B6: Unit | C6: 800 | D6: 50 | E6: 50 | F6: Anima | G6: 3 | H6: Immune to 0-cost Traps | J6: Yes | K6: =(D6*6)+(E6*4) -> 500 | L6: Yes | N6: Yes
A7: Fierce Gladiator | B7: Unit | C7: 1000 | D7: 70 | E7: 90 | F7: Anima | G7: 3 | H7: +200 Crystal if successfully defended | J7: Yes | K7: =(D7*6)+(E7*4) -> 780 | L7: Yes
A8: Canyon Warg | B8: Unit | C8: 750 | D8: 70 | E8: 30 | F8: Nature | G8: 3 | H8: None | J8: Yes | K8: =(D8*6)+(E8*4) -> 540 | L8: Yes | P8: Yes
A9: Armored Bee | B9: Unit | C9: 480 | D9: 30 | E9: 0 | F9: Nature | G9: 2 | H9: +60 DEF until the end of that turn once | J9: Yes | K9: =(D9*6)+(E9*4) -> 180 | L9: Yes | N9: Yes
A10: Armored Rhino | B10: Unit | C10: 720 | D10: 60 | E10: 85 | F10: Nature | G10: 3 | H10: None | J10: Yes | K10: =(D10*6)+(E10*4) -> 700 | L10: Yes | O10: Yes
A11: Lightbringer | B11: Unit | C11: 1200 | D11: 80 | E11: 40 | F11: Divine | G11: 3 | H11: +100 DEF vs Chaos Affinity | J11: Yes | K11: =(D11*6)+(E11*4) -> 640
A12: Chaotic Wisp | B12: Unit | C12: 100 | D12: 20 | E12: 0 | F12: Chaos | G12: 1 | H12: None | J12: Yes | K12: =(D12*6)+(E12*4) -> 120 | L12: Yes
A13: Foul Wisp | B13: Unit | C13: 100 | D13: 0 | E13: 25 | F13: Chaos | G13: 1 | H13: None | J13: Yes | K13: =(D13*6)+(E13*4) -> 100 | L13: Yes | N13: Yes
A14: Doom Wisp | B14: Unit | C14: 100 | D14: 15 | E14: 15 | F14: Chaos | G14: 1 | H14: None | J14: Yes | K14: =(D14*6)+(E14*4) -> 150 | L14: Yes | N14: Yes
A15: Night Whisperer | B15: Unit | C15: 900 | D15: 30 | E15: 30 | F15: Chaos | G15: 3 | H15: +30 ATK&DEF for each exposed ‘wisp’ card on your side | J15: Yes | K15: =(D15*6)+(E15*4) -> 300 | L15: Yes | O15: Yes
A16: Leorudus the Warlord | B16: Unit | C16: 1150 | D16: 80 | E16: 80 | F16: Anima | G16: 5 | H16: +20 ATK&DEF for each other exposed Anima card on your side | J16: Yes | K16: =(D16*6)+(E16*4) -> 800 | L16: Yes | O16: Yes
A17: Aether Warden | B17: Unit | C17: 800 | D17: 30 | E17: 110 | F17: Divine | G17: 3 | H17: In Reckoning if it defends, attacker loses 300 Crystals | J17: Yes | K17: =(D17*6)+(E17*4) -> 620
A18: Void Stalker | B18: Unit | C18: 720 | D18: 65 | E18: 25 | F18: Chaos | G18: 3 | H18: +20 ATK if it attacks an exposed card. | J18: Yes | K18: =(D18*6)+(E18*4) -> 490 | L18: Yes | N18: Yes
A19: Swarmcaller | B19: Unit | C19: 950 | D19: 45 | E19: 45 | F19: Nature | G19: 4 | H19: +15 ATK&DEF for each other exposed Nature card on your side | J19: Yes | K19: =(D19*6)+(E19*4) -> 450 | L19: Yes | N19: Yes
A20: Ironclad Sentinel | B20: Unit | C20: 1100 | D20: 55 | E20: 95 | F20: Anima | G20: 5 | H20: Immune to 0-cost Traps. This Unit cannot be destroyed by Tech Cards. | J20: Yes | K20: =(D20*6)+(E20*4) -> 710
A21: Tomb Bandit | B21: Unit | C21: 1000 | D21: 75 | E21: 60 | F21: Anima | G21: 4 | H21: This Unit cannot be destroyed by Traps. It gets -20 DEF permanently if it attacked a trap card. | J21: Yes | K21: =(D21*6)+(E21*4) -> 690 | L21: Yes | P21: Yes
A22: Scout Probe | B22: Unit | C22: 700 | D22: 40 | E22: 50 | F22: Cosmic | G22: 3 | H22: After this card attacks, choose and reveal 1 adjacent cell. | J22: Yes | K22: =(D22*6)+(E22*4) -> 440 | L22: Yes | N22: Yes
A23: Lab Zombie | B23: Unit | C23: 700 | D23: 55 | E23: 20 | F23: Bio | G23: 3 | H23: With Mutagen Flag: +45 ATK vs Nature or Anima. | J23: Yes | K23: =(D23*6)+(E23*4) -> 410 | L23: Yes | O23: Yes
A24: Lab Bloater | B24: Unit | C24: 800 | D24: 20 | E24: 85 | F24: Bio | G24: 4 | H24: With Mutagen Flag: Destroy both units in Reckoning. Both players pay no cost. | J24: Yes | K24: =(D24*6)+(E24*4) -> 460 | L24: Yes | P24: Yes
A25: Lab Crawler | B25: Unit | C25: 1200 | D25: 95 | E25: 60 | F25: Bio | G25: 5 | H25: With Mutagen Flag: this card can target 3 cards | J25: Yes | K25: =(D25*6)+(E25*4) -> 810 | L25: Yes | N25: Yes
A26: Pit Lord | B26: Unit | C26: 1250 | D26: 120 | E26: 100 | F26: Chaos | G26: 5 | H26: Destroy this card after Reckoning with Divine Unit. After this card attacked, halve its ATK&DEF permanently | J26: Yes | K26: =(D26*6)+(E26*4) -> 1120 | L26: Yes | O26: Yes
A27: Ancient Lich | B27: Unit | C27: 750 | D27: 60 | E27: 60 | F27: Chaos | G27: 3 | H27: This card is unaffected by Tech cards. | J27: Yes | K27: =(D27*6)+(E27*4) -> 600
A28: Hyperspeed Saucer | B28: Unit | C28: 850 | D28: 80 | E28: 40 | F28: Cosmic | G28: 4 | H28: Permanently increase this card's ATK&DEF by 10 at the end of each of your turn | J28: Yes | K28: =(D28*6)+(E28*4) -> 640
A29: Mountain Sage | B29: Unit | C29: 600 | D29: 50 | E29: 30 | F29: Arcane | G29: 3 | H29: Double effect of Tech card applied to this unit | J29: Yes | K29: =(D29*6)+(E29*4) -> 420
A30: War Genie | B30: Unit | C30: 1150 | D30: 100 | E30: 80 | F30: Arcane | G30: 4 | H30: -10 ATK permanently after it attacked | J30: Yes | K30: =(D30*6)+(E30*4) -> 920 | L30: Yes | P30: Yes
A31: Grand Wizard | B31: Unit | C31: 1100 | D31: 90 | E31: 70 | F31: Arcane | G31: 4 | H31: In Reckoning, flip a coin. Head: +30 ATK&DEF until this turn’s end | J31: Yes | K31: =(D31*6)+(E31*4) -> 820
A32: Archbishop | B32: Unit | C32: 1200 | D32: 70 | E32: 90 | F32: Divine | G32: 4 | H32: If this card would be destroyed, you can destroy 1 other Divine card on your side instead | J32: Yes | K32: =(D32*6)+(E32*4) -> 780 | L32: Yes | P32: Yes
A33: Space Boy | B33: Unit | C33: 800 | D33: 75 | E33: 65 | F33: Cosmic | G33: 3 | H33: None | J33: Yes | K33: =(D33*6)+(E33*4) -> 710 | L33: Yes | O33: Yes
A34: Slim Gray Trooper | B34: Unit | C34: 800 | D34: 45 | E34: 45 | F34: Cosmic | G34: 2 | H34: +65 ATK&DEF if 10 or more cells on your side are revealed | J34: Yes | K34: =(D34*6)+(E34*4) -> 450
A35: Horn Face | B35: Unit | C35: 1350 | D35: 85 | E35: 60 | F35: Cosmic | G35: 5 | H35: After a successful attack, flip 2 coins. It can attack again equal to number of head. | J35: Yes | K35: =(D35*6)+(E35*4) -> 750
A36: Railgun Tank | B36: Unit | C36: 1500 | D36: 150 | E36: 95 | F36: Anima | G36: 5 | H36: After a successful attack, this card cannot attack on the next of your turn. | J36: Yes | K36: =(D36*6)+(E36*4) -> 1280 | L36: Yes
A37: Lazy Troll | B37: Unit | C37: 1000 | D37: 120 | E37: 60 | F37: Nature | G37: 5 | H37: If this card performs an attack, flip a coin. Tail: it stops attacking. | J37: Yes | K37: =(D37*6)+(E37*4) -> 960 | L37: Yes | N37: Yes
A38: Leech Man | B38: Unit | C38: 880 | D38: 60 | E38: 40 | F38: Bio | G38: 4 | H38: +10 DEF permanently after it performed attack on unit. Also +10 ATK with mutagen flag | J38: Yes | K38: =(D38*6)+(E38*4) -> 520 | L38: Yes | O38: Yes
A39: Immortal Vampire | B39: Unit | C39: 1200 | D39: 30 | E39: 80 | F39: Chaos | G39: 4 | H39: +30 ATK for each other exposed Chaos card on your side. In Reckoning with Divine, destroy this card. | J39: Yes | K39: =(D39*6)+(E39*4) -> 500 | L39: Yes | N39: Yes
A40: Vampire Servant | B40: Unit | C40: 800 | D40: 20 | E40: 20 | F40: Chaos | G40: 2 | H40: If a 'Vampire' card will be destroyed, destroy this card instead. Usable face-down. | J40: Yes | K40: =(D40*6)+(E40*4) -> 200 | L40: Yes | O40: Yes
...

Sheet Union
A1: Table 1
A2: Card Name | B2: Union | C2: Cost | D2: ATK | E2: DEF | F2: Affinity | G2: Rarity | H2: Partial Ability | I2: Full Ability | J2: Partial Formula | K2: Full Formula | L2: Union Zone | M2: Have illustration | N2: Demo | O2: Test 1
A3: Gryphon Rider | B3: Union | D3: 125 | E3: 90 | F3: Divine | H3: None | I3: None | J3: 1 ??? + 1 ??? + 1000 cost | K3: Gryphon + 1 Divine + 1000 cost | L3: 10000 01000 00100 00010 00001 | M3: Yes | N3: Yes
A4: Seraphim Fistmaster | B4: Union | D4: 120 | E4: 120 | F4: Divine | H4: Double ATK&DEF against ??? Affinity | I4: Double ATK&DEF against Chaos | J4: 1 ??? + 1 ??? + 1500 cost | K4: 1 ‘Seraph’ unit + 1 Divine (≥ 800 cost) + 1500 cost | L4: 11011 10001 00000 10001 11011 | M4: Yes | N4: Yes
A5: Gaia Turtle | B5: Union | D5: 0 | E5: 210 | F5: Nature | H5: None | I5: None | J5: 2 ??? + 2000 cost | K5: 2 any units (≥90 DEF) + 2000 cost | L5: 00000 00000 01110 01110 00000 | M5: Yes | N5: Yes
A6: Barros the Colossal | B6: Union | D6: 150 | E6: 130 | F6: Nature | H6: None | I6: None | J6: 2 ???+ 1500 cost | K6: 2 Nature (≥ 800 cost) + 1500 cost | L6: 00000 01010 00100 01010 00000 | M6: Yes | N6: Yes
A7: X-Death Squad | B7: Union | D7: 50 | E7: 50 | F7: Anima | H7: In Reckoning, pay ???, destroy foe’s unit. They pay ???. | I7: In Reckoning, pay 1000, destroy foe’s unit. They pay no cost. | J7: 1 ??? + 2 ??? + 800 cost | K7: 1 Anima (≥ 800 cost) + 2 Anima + 800 cost | L7: 10101 00000 10101 00000 10101 | M7: Yes | N7: Yes
A8: Rocket Marauder | B8: Union | D8: 125 | E8: 105 | F8: Bio | H8: None | I8: None | J8: 1 ??? + 1 ??? + 1000 cost | K8: 1 Bio (≥ 800 cost) + 1 Anima (≥ 800 cost) + 1000 cost | L8: 00000 00000 00000 01010 10101 | M8: Yes | N8: Yes
A9: Lord of Terror | B9: Union | D9: 150 | E9: 100 | F9: Chaos | H9: -50 ATK if ??? | I9: -50 ATK if attacks Dead End | J9: 2 ??? + 1500 cost | K9: 2 Chaos (≥ 800 cost) + 1500 cost | L9: 00000 00100 00100 01110 00100 | M9: Yes | N9: Yes
A10: Armored Dino | B10: Union | D10: 95 | E10: 60 | F10: Nature | H10: In Reckoning, pay ??? Crystal cost to +??DEF | I10: In Reckoning, pay 1000 Crystal cost to +60 DEF | J10: 1 ??? + 1 ??? + 700 cost | K10: 1 Armored Nature card + 1 Nature (≥ 700 cost) + 800 cost | L10: 00000 01110 11111 00000 00000 | M10: Yes | N10: Yes
A11: Greater Succubus | B11: Union | D11: 30 | E11: 50 | F11: Chaos | H11: Once, after Reckoning: +ATK&DEF equal to ??? | I11: Once, after Reckoning: +ATK&DEF equal to half of that foe’s card | J11: 1 ??? + 1 ??? + 800 cost | K11: 1 Succubus + 1 Chaos + 800 cost | L11: 00100 11111 10001 00000 00000 | M11: Yes | N11: Yes
A12: Pixie Queen | B12: Union | D12: 30 | E12: 30 | F12: Divine | H12: +5 ATK for each ???? | I12: +5 ATK for each Divine cards on your side | J12: 1 ??? + 1 ??? + 300 cost | K12: 1 Tiny Pixie + 1 Divine+ 300 cost | L12: 00100 00100 10001 10101 01010 | M12: Yes | N12: Yes
A13: Diamond Unicorn | B13: Union | D13: 30 | E13: 35 | F13: Divine | H13: Summoned: ??? until this turn’s end | I13: Summoned: +15 ATK until this turn’s end | J13: 1 ??? + 1 ??? + 500 cost | K13: 1 Ponycorn + 1 Divine card + 500 cost | L13: 00100 01010 10001 01010 00100 | M13: Yes | N13: Yes
A14: Choir Lead Amber | B14: Union | D14: 35 | E14: 35 | F14: Divine | H14: +20 ATK to all ????? | I14: +20 ATK to all Divine units on your side | J14: 3 ??? + 500 cost | K14: 3 Choir Lady cards + 500 cost | L14: 01100 01011 01001 11000 11000 | M14: Yes | N14: Yes
... A36: Giant Meteor Vergaia | B36: Union | D36: 60 | E36: 0 | F36: Cosmic | H36: Destroy it at turn's end, then destroy all ??? | I36: Destroy it at turn's end, then destroy all exposed foe’s units surrounding the card that this card attacked. | J36: ??? + ??? + 1000 cost | K36: Striker Comet + 2 Cosmic card + 1000 cost | L36: 10000 01000 00000 00111 00111 | M36: Yes | N36: Yes
A37: Blood-hungry Mutant | B37: Union | D37: 55 | E37: 40 | F37: Bio | H37: After destroying foe’s card: ??? | I37: After destroying foe’s card: +80 Crystals | J37: 2 ??? + 600 cost | K37: 2 Mutant cards + 600 cost | L37: 00000 01010 10101 01010 00000 | M37: Yes
A38: Gamma Mermaid | B38: Union | D38: 30 | E38: 20 | F38: Bio | H38: Non-Bio defender get ???. With Mutagen Flag: +20 ??? | I38: Non-Bio defender get -20 DEF. With Mutagen Flag: +20 ATK&DEF to all ally Bio units | J38: ??? + ??? + 1000 cost | K38: 1 Gamma cards + 1 Bio card + 500 cost | L38: 00000 01110 01010 01110 00000 | M38: Yes | N38: Yes
A39: Tendrill Tyrant | B39: Union | D39: 90 | E39: 110 | F39: Bio | H39: Can attack ? times per turn | I39: Can attack 3 times per turn | J39: 1 ??? + 2 ??? + 1500 cost | K39: 1 Bio with mutagen flag + 2 Bio (≥ 800 cost) + 1500 cost | L39: 00100 00100 11111 00100 00100
A40: Helios the Prideful Fortress | B40: Union | D40: 145 | E40: 60 | F40: Cosmic | H40: As long as there is exposed ???, this card cannot be ???. If targeted by tech, ??? | I40: With another exposed Cosmic: this card cannot be destroyed. If targeted by tech, destroy this card. | J40: 2 ??? + 1500 cost | K40: 2 Cosmic (≥ 800 cost) + 1500 cost | L40: 00100 01010 10001 01010 00100 | M40: Yes | N40: Yes
A41: Slim Gray Plasma Bomber | B41: Union | D41: 80 | E41: 60 | F41: Cosmic | H41: +?? ATK&DEF if ?? or more of cells on your side are revealed | I41: +100 ATK&DEF if 10 or more cells on your side are revealed | J41: 1 ??? + 1 ??? + 1000 cost | K41: 1 Slim Gray + 1 Cosmic (≥ 800 cost) + 1000 cost | L41: 00100 01110 01010 01110 00000
A42: Interplanetary Assassin | B42: Union | D42: 50 | E42: 70 | F42: Cosmic | H42: +?? ATK vs Cosmic | I42: +100 ATK vs Cosmic | J42: 1 ??? + 1 ??? + 1500 cost | K42: 1 Cosmic (≥ 500 cost) + 1 Cosmic + 1500 cost | L42: 00100 11111 00000 11111 00100
A43: Bioterrorist | B43: Union | D43: 150 | E43: 0 | F43: Bio | H43: Destroy this card after ??? | I43: Destroy this card after Reckoning | J43: 2 ??? + 1000 cost | K43: 2 Bio cards (≥ 800 cost) + 1000 cost | L43: 10001 01010 00000 01010 10001 | M43: Yes | N43: Yes
A44: One Winged Angel | B44: Union | D44: 120 | E44: 120 | F44: Divine | H44: +??? ATK permanently at ??? | I44: +30 ATK permanently at the end of your turn (max 120) | J44: 1 ??? + 1 ??? + 1500 cost | K44: 1 Cleaver Saint + 1 Divine card + 1500 cost | L44: 00011 00011 00011 00011 00011
A45: Genesis Mech | B45: Union | D45: 60 | E45: 40 | F45: Divine | H45: Once, destroy ???or ??? card | I45: Once, destroy Divine or Anima card | J45: 1 ??? + 1 ??? + 1000 cost | K45: 1 Mean Angel + 1 Anima Card + 1000 cost | L45: 11111 11111 00000 00000 00000
A46: Keeper of the Afterlife | B46: Union | D46: 40 | E46: 65 | F46: Divine | H46: At Reckoning, flip a coin. If head, ???? | I46: At Reckoning, flip a coin. If head, the attack does nothing | J46: 1 ??? + 1 ???+ 1000 cost | K46: 1 Sphinx unit + 1 Divine card + 1000 cost | L46: 00000 00000 00100 01110 11111
A47: Keeper of the Sun | B47: Union | D47: 70 | E47: 35 | F47: Divine | H47: This card cannot attack if there is card with affinity other than ??? Or ??? | I47: This card cannot attack if there is card with affinity other than Divine or Anima on your side | J47: 1 ???+ ??? + 1000 cost | K47: 1 Sphinx unit + 1 Anima + 1000 cost | L47: 11111 01110 00100 00000 00000
A48: Keeper of Righteous | B48: Union | D48: 90 | E48: 80 | F48: Divine | H48: +??? ATK vs ?? and ?? | I48: +20 ATK vs Chaos and Arcane | J48: 2 ???+ 1000 cost | K48: 2 Sphinx units + 1000 cost | L48: 10001 01010 00100 01010 10001
A49: Lucky Wanderer | B49: Union | D49: 70 | E49: 50 | F49: Divine | H49: During the end of that turn, flip a coin. If head, +??? ATK. If tail, +?? DEF | I49: During the end of that turn, flip a coin. If head, +10 ATK. If tail, +10 DEF | J49: 1 ??? + 1 ??? + 1000 cost | K49: 1 Lucky Statue + 1 Divine card + 1000 cost | L49: 00100 00100 00100 00100 00100
A50: Joyce the Rafflesia | B50: Union | D50: 45 | E50: 45 | F50: Divine | H50: At the end of this turn, +??? ATK&DEF ???? | I50: At the end of this turn, +5 ATK&DEF permanently. | J50: 1 ??? + 1 ??? + 1000 cost | K50: Bloom Fairy + 1 Nature card + 1000 cost | L50: 11111 11011 00100 00100 00100
A51: Twin Axe Saintess | B51: Union | D51: 40 | E51: 30 | F51: Divine | H51: This card can ??? per turn | I51: This card can attack twice per turn | J51: 1??? + 1 ??? + 1000 cost | K51: Lady of the Sacred Pond + 1 Anima + 600 cost | L51: 11011 01010 01010 01010 00000
A52: Blast Beam Seraph | B52: Union | D52: 100 | E52: 50 | F52: Divine | H52: None | I52: None | J52: 1 ??? + 1 ??? + 1000 cost | K52: Gerald of the Heavenly Light + 1 Divine + 1000 cost | L52: 11111 00100 11111 00100 00000
A53: Balthier the Supreme Holiness | B53: Union | D53: 100 | E53: 100 | F53: Divine | H53: +??? ATK&DEF for each ???cards on the field. | I53: +50 ATK&DEF for each Divine cards on the field. | J53: 2 ??? + 1500 cost | K53: 3 Divine (≥800 cost) + 1500 cost | L53: 00100 11111 00100 00100 00100
A54: Oblivion Dragon | B54: Union | D54: 200 | E54: 0 | F54: Chaos | H54: When this card defends, halve its ??? an??? | I54: When this card defends, halve its attack and gain DEF by that amount permanently | J54: 4 ??? + 2000 cost | K54: 4 Chaos card (≥500 cost) + 2000 cost | L54: 10001 00100 01010 00000 10001
A55: Big Bang Dragon | B55: Union | D55: 250 | E55: 180 | F55: Nature | H55: Summoned: destroy all ??? | I55: Summoned: destroy all other exposed ally units. No paid cost. | J55: 5 ??? + 2500 cost | K55: 5 Cosmic cards + 2500 cost | L55: 00001 00010 00100 01000 10000
... A64: Cullan the Flaming Blade | B64: Union | D64: 40 | E64: 30 | F64: Arcane | H64: +??? ATK&DEF vs Nature | I64: +30 ATK&DEF vs Nature | J64: 1 ??? + 1 ??? + 1000 cost | K64: Cullan the Magic Swordsman + Red Mage + 1000 cost | L64: 00001 00010 01100 01110 10000
A65: The Undertaker | B65: Union | D65: 90 | E65: 75 | F65: Chaos | H65: If foe destroys a card on your side, gain ??? | I65: If foe destroys a card on your side, gain +15 ATK permanently (max 90). | K65: Sinister Cultist + 1 Chaos card + 1000 cost | L65: 00000 00000 01110 01110 01110
A66: Ethereal Marquees | B66: Union | D66: 195 | E66: 180 | F66: Arcane | H66: -80 DEF if ??? | I66: -80 DEF vs Arcane card. If this survived Reckoning, pay 500 cost | K66: Nobleman card + Ethereal card + 1500 cost | L66: 00100 01010 10101 01010 10101
A67: Charm Mistress | B67: Union | D67: 30 | E67: 50 | F67: Arcane | H67: Foe’s turn start: flip a coin. Head, ??? | I67: Foe’s turn start: flip a coin. Head, foe can only attack once. | K67: Alluring Spellcaster + 1 Arcane + 1000 cost | L67: 00000 01010 01110 00100 00000
A68: Chronomancer | B68: Union | D68: 60 | E68: 80 | F68: Arcane | H68: For cannot revive or create token copy a unit. Once, after Arcane unit is destroyed, ??? | I68: For cannot revive or create token copy a unit. Once, after Arcane unit is destroyed, revive it. | K68: Freya the Rift Walker + Bingo the Chrono Rabbit + 1000 cost. | L68: 00010 01000 00010 01000 00001
A69: Death Colony | B69: Union | D69: 225 | E69: 150 | F69: Bio | H69: This card can only choose attack target in the same pattern as ??? | I69: This card can only choose attack target in the same pattern as its union zone | K69: Long Tongue + 1 Bio card + 1500 cost. | L69: 10001 01010 00100 01010 10001
...

Sheet Trap
A1: Table 1
A2: Card Name | B2: Card Type | C2: Cost | D2: ATK | E2: DEF | F2: Affinity | G2: Rarity | H2: Ability | I2: Formula | J2: Have illustration | K2: Suggested cost | L2: Demo | M2: Test 1 | N2: ="Booster Pack - Blightsilver / "&COUNTIF(N3:N544,"Yes") -> Booster Pack - Blightsilver / 8 | O2: ="Booster Pack - Unseen Presence / "&COUNTIF(O3:O544,"Yes") -> Booster Pack - Unseen Presence / 8 | P2: ="Booster Pack - Wind of Dominance / "&COUNTIF(P3:P544,"Yes") -> Booster Pack - Wind of Dominance / 5
A3: Trap Hole | B3: Trap | C3: 0 | G3: 1 | H3: Flip 3 coin, attacking player loses 20 Crystals per each head(s). | J3: Yes | L3: Yes
A4: Hostage | B4: Trap | C4: 500 | G4: 2 | H4: Usable when foe attacks. You can reveal one of your unit. Until this turn ends, foe cannot target that unit. If already targeted it, foe must choose other cell. | J4: Yes | L4: Yes | N4: Yes
A5: Bait | B5: Trap | C5: 0 | G5: 1 | H5: You choose one other cell on your side and reveal it. | J5: Yes | L5: Yes | N5: Yes
A6: Blackmail | B6: Trap | C6: 0 | G6: 2 | H6: The attacker chooses either discarding 1 Tech Card or end the turn immediately | J6: Yes | L6: Yes | N6: Yes
A7: Cursed Reflection | B7: Trap | C7: 600 | G7: 3 | H7: Swap the attacking unit's ATK&DEF until the end of your turn. | J7: Yes | L7: Yes | O7: Yes
A8: Explosive Barrels | B8: Trap | C8: 0 | G8: 5 | H8: Destroy the attacking unit. You also pay the same cost as attacker. | J8: Yes | L8: Yes | P8: Yes
A9: Hypnosis | B9: Trap | C9: 500 | G9: 4 | H9: The attacking unit cannot attack during the foe's next turn. | J9: Yes | L9: Yes | N9: Yes
A10: Flame Trap | B10: Trap | C10: 200 | G10: 2 | H10: The attacking unit gets -10 ATK permanently. | J10: Yes | L10: Yes | O10: Yes
A11: Echo Barrier | B11: Trap | C11: 400 | G11: 3 | H11: This turn, foe cannot perform any more attack. | J11: Yes | L11: Yes | O11: Yes
A12: Mana Drain | B12: Trap | C12: 200 | G12: 2 | H12: Foe loses 300 Crystals. You gain 300 Crystals. | J12: Yes | L12: Yes
A13: Defensive Pheromone | B13: Trap | C13: 400 | G13: 3 | H13: You switch 1 'Armored' Nature card on your side with this cell, then repeat Reckoning. | J13: Yes | L13: Yes | O13: Yes
A14: Spike Trap | B14: Trap | C14: 800 | G14: 5 | H14: Destroy the attacking unit | J14: Yes | L14: Yes | P14: Yes
A15: Snare Trap | B15: Trap | C15: 500 | G15: 4 | H15: The attacking unit's ability becomes None until attacker’s next turn ends | J15: Yes | L15: Yes | P15: Yes
A16: Brainwash | B16: Trap | C16: 800 | G16: 5 | H16: The attacker chooses their own ally as an attack target | J16: Yes | L16: Yes | O16: Yes
A17: Bunker | B17: Trap | C17: 800 | G17: 4 | H17: Usable when foe attack this card or surround cells. Foe cannot target surrounding cells until the end of this turn. If already targeted, they must choose other cell. | J17: Yes | L17: Yes | P17: Yes
A18: Foul Gas | B18: Trap | C18: 0 | G18: 3 | H18: -5 ATK to all the attacking player’s units until the end of this turn | J18: Yes | L18: Yes | N18: Yes
A19: Choking Gas | B19: Trap | C19: 200 | G19: 4 | H19: -20 ATK to all the attacking player’s units until the end of this turn | J19: Yes | L19: Yes
A20: Radiation | B20: Trap | C20: 600 | G20: 4 | H20: Attacking unit permanently lose 10 ATK&DEF. it loses more 10 ATK&DEF for each trap cards in your void | J20: Yes | L20: Yes
A21: Acid Trap Hole | B21: Trap | C21: 0 | G21: 1 | H21: Flip 2 coin, attacking player loses 50 Crystals per each head(s). | J21: Yes | L21: Yes | N21: Yes
A22: Lava Trap Hole | B22: Trap | C22: 50 | G22: 2 | H22: Flip 3 coin, attacking player loses 100 Crystals per each head(s). | J22: Yes | L22: Yes
A23: Fissure | B23: Trap | C23: 100 | G23: 3 | H23: Attacking player loses 200 Crystals | J23: Yes
A24: Soul Blast | B24: Trap | C24: 800 | G24: 5 | H24: Attacking player lose 150 Crystals for each unit cards in your void | J24: Yes | L24: Yes
A25: Grudge | B25: Trap | C25: 600 | G25: 2 | H25: -10 ATK to the attacking unit permanently for each unit cards in your void | J25: Yes | L25: Yes
A26: Anti-virus | B26: Trap | C26: 400 | G26: 1 | H26: If attacker is Bio, flip a coin. Head: destroy it. Always head, if your Crystal is 1000 or less. | J26: Yes
A27: Witch Hunt | B27: Trap | C27: 400 | G27: 1 | H27: If attacker is Arcane, flip a coin. Head: destroy it. Always head, if your Crystal is 1000 or less. | J27: Yes
A28: Standoff | B28: Trap | C28: 400 | G28: 1 | H28: If attacker is Anima, flip a coin. Head: destroy it. Always head, if your Crystal is 1000 or less. | J28: Yes
A29: Apple of Adam | B29: Trap | C29: 400 | G29: 1 | H29: If attacker is Divine, flip a coin. Head: destroy it. Always head, if your Crystal is 1000 or less. | J29: Yes
A30: Purify | B30: Trap | C30: 400 | G30: 1 | H30: If attacker is Chaos, flip a coin. Head: destroy it. Always head, if your Crystal is 1000 or less. | J30: Yes
A31: Solar Flare | B31: Trap | C31: 400 | G31: 1 | H31: If attacker is Cosmic, flip a coin. Head: destroy it. Always head, if your Crystal is 1000 or less. | J31: Yes
A32: Hunting Season | B32: Trap | C32: 400 | G32: 1 | H32: If attacker is Nature, flip a coin. Head: destroy it. Always head, if your Crystal is 1000 or less. | J32: Yes
A33: Dart Trap | B33: Trap | C33: 350 | G33: 2 | H33: If the attacking unit is the first one to attack in that turn, -50 DEF | J33: Yes
A34: Science Cage | B34: Trap | C34: 250 | G34: 3 | H34: If attacker Is Bio affinity, end their turn immediately. Remove all flags from it. | J34: Yes
A35: Loop Hole | B35: Trap | C35: 250 | G35: 3 | H35: If attacker is Arcane, its ability become None permanently. | J35: Yes
A36: Talisman of Light | B36: Trap | C36: 250 | G36: 3 | H36: If attacker is Chaos, -50 ATK to that unit permanently | J36: Yes
A37: Forbidden Grail | B37: Trap | C37: 250 | G37: 3 | H37: If attacker is Divine, -50 DEF to that unit permanently | J37: Yes
... A40: Galaxy Toll | B40: Trap | C40: 250 | G40: 3 | H40: If attacker is Cosmic, foe loses 1000 Crystals | J40: Yes
A41: Union Cage | B41: Trap | C41: 400 | G41: 3 | H41: Usable if a Union card attack this card or the surround cell. That Union card cannot attack until the attacker’s next turn ends. | J41: Yes | L41: Yes
A42: Plunder | B42: Trap | C42: 500 | G42: 4 | H42: The attacker chooses to let you receive 1000 Crystals, or destroy the attacking unit. | J42: Yes | L42: Yes
...

Sheet Tech
A1: Table 1
A2: Card Name | B2: Card Type | C2: Cost | D2: ATK | E2: DEF | F2: Affinity | G2: Rarity | H2: Ability | I2: Formula | J2: Illustration | K2: Suggested cost | L2: Demo | M2: Test 1 | N2: ="Booster Pack - Blightsilver / "&COUNTIF(N3:N545,"Yes") -> Booster Pack - Blightsilver / 4 | O2: ="Booster Pack - Unseen Presence / "&COUNTIF(O3:O545,"Yes") -> Booster Pack - Unseen Presence / 2 | P2: ="Booster Pack - Wind of Dominance / "&COUNTIF(P3:P545,"Yes") -> Booster Pack - Wind of Dominance / 5
A3: Welcoming Door | B3: Tech | C3: 0 | G3: 1 | H3: Choose any square on your side and reveal it | J3: Yes
A4: Spy | B4: Tech | C4: 0 | G4: 1 | H4: Reveal 1 of foe’s cell | J4: Yes | L4: Yes
A5: Ceasefire | B5: Tech | C5: 0 | G5: 3 | H5: Both players skip 1 turn (tax is forced to apply) | J5: Yes
A6: Make Friend | B6: Tech | C6: 0 | G6: 5 | H6: Both players select 1 unit from their side. That unit cannot attack until your next turn ends | J6: Yes
A7: Double Spy | B7: Tech | C7: 0 | G7: 2 | H7: Only trigger if you have Spy card in the void. Reveal 2 cells on foe's side. | J7: Yes
A8: Invisible Spy | B8: Tech | C8: 0 | G8: 3 | H8: Only trigger if you have Double Spy card in the void. Reveal 2 cells on foe's side. | J8: Yes
A9: Corrupted Spy | B9: Tech | C9: 0 | G9: 4 | H9: Reveal 3 cells on foe’s side. If any trap or unit is found, you pays 700 Crystal for each card found. | J9: Yes
A10: Tease | B10: Tech | C10: 0 | G10: 2 | H10: Foe chooses and reveal 1 of their cell | J10: Yes | L10: Yes
A11: Bribe | B11: Tech | C11: 0 | G11: 3 | H11: Foe can choose to reveal a unit card and receive 700 Crystals or do nothing | J11: Yes | L11: Yes | N11: Yes
A12: Release Mutagen | B12: Tech | C12: 0 | G12: 4 | H12: Add Mutagen Flag to 1 of your unit | J12: Yes | L12: Yes | O12: Yes
A13: Prayer | B13: Tech | C13: 0 | G13: 4 | H13: Once, until foe’s turn ends: prevent Divine card from being destroyed | J13: Yes | L13: Yes | O13: Yes
A14: Arcane Nova | B14: Tech | C14: 2500 | G14: 5 | H14: Destroy up to 3 exposed foe units (no cost is paid). You discard all of your tech cards afterward. | J14: Yes
A15: Rift Strike | B15: Tech | C15: 2000 | G15: 3 | H15: Select 3 adjacent cells on foe’s field and destroy it. No cost is paid | J15: Yes | L15: Yes
A16: Great Diplomacy | B16: Tech | C16: 1000 | G16: 4 | H16: You select up to 3 of your units and reveal them. | J16: Yes | L16: Yes | P16: Yes
A17: War Supply | B17: Tech | C17: 1000 | G17: 3 | H17: Your units get +10 ATK&DEF in Reckoning until the end of the turn. | J17: Yes | L17: Yes | N17: Yes
A18: Harsh Training | B18: Tech | C18: 500 | G18: 2 | H18: Select 1 of your units. It gains +10 ATK permanently. | J18: Yes | N18: Yes
A19: Illegal Steroid | B19: Tech | C19: 1000 | G19: 4 | H19: +30 ATK for 1 unit until the end of this turn. | J19: Yes
A20: Secret Dagger | B20: Tech | C20: 600 | G20: 3 | H20: Can only be used on face-down card. Turn that card exposed and +15 ATK until the end of this turn. | J20: Yes
A21: Garrison | B21: Tech | C21: 1500 | G21: 4 | H21: Until foe's turn ends: +20 DEF to all your cards in Reckoning | J21: Yes | L21: Yes
A22: Bulletproof Vest | B22: Tech | C22: 850 | G22: 3 | H22: +15 DEF permanently for 1 exposed unit. If use on face-down card, flip it up. | J22: Yes
A23: Siege Cannon | B23: Tech | C23: 1000 | G23: 5 | H23: Until the end of this turn, once, foe’s defending unit is destroyed. | J23: Yes | L23: Yes | P23: Yes
A24: Assassinate | B24: Tech | C24: 1500 | G24: 4 | H24: Destroy 1 of foe’s exposed card | J24: Yes
A25: Accident | B25: Tech | C25: 1000 | G25: 3 | H25: Destroy 1 of foe’s exposed card. If there is no exposed card, foe must choose the target. foe pays no cost. | J25: Yes | L25: Yes | P25: Yes
A26: Berserk | B26: Tech | C26: 900 | G26: 5 | H26: You gain 1 attack count until the end of this turn | J26: Yes | L26: Yes
A27: Radar | B27: Tech | C27: 600 | G27: 1 | H27: Reveal 3 of foe’s cell | J27: Yes | L27: Yes | N27: Yes
A28: Palace Party | B28: Tech | C28: 500 | G28: 2 | H28: You reveal 1 face-down unit. Foe must reveal 1 of their face-down unit (if any) | J28: Yes
A29: Essence Transfer | B29: Tech | C29: 700 | G29: 5 | H29: You chooses 1 unit. Copy all its ATK&DEF bonuses or debuffs to another ally unit (if valid) until the end of this turn. | J29: Yes
A30: Blood Ritual | B30: Tech | C30: 1000 | G30: 4 | H30: Destroy 1 card on your side (No paid cost). Choose 1 of foe's exposed unit. Its ATK&DEF becomes 0 permanently | J30: Yes
A31: Arcane Duplication | B31: Tech | C31: 1000 | G31: 5 | H31: You. Choose 1 unit. Create a token copy of it on an empty cell. Destroy it at the end of your next turn. | J31: Yes
A32: Time Travel | B32: Tech | C32: 1800 | G32: 5 | H32: Once only, revive 1 unit to any unoccupied or empty cell in exposed position. Double its Crystal cost. | J32: Yes
A33: Resurrection | B33: Tech | C33: 1500 | G33: 4 | H33: Once, revive 1 unit. It has no ATK,DEF, or ability. | J33: Yes | L33: Yes | P33: Yes
A34: Tech Copy | B34: Tech | C34: 1000 | G34: 3 | H34: Foe show 1 tech card in their hand. Add a copy of that card into your Tech Stack.
A35: Force Shield | B35: Tech | C35: 600 | G35: 2 | H35: You selects 1 unit. It is not destroyed until the end of foe's turn
A36: Wisp Light | B36: Tech | C36: 250 | G36: 3 | H36: Destroy as many ally ‘wisp’ units. Reveal that much cells on foe's side.
A37: Lucky Day | B37: Tech | C37: 300 | G37: 2 | H37: Flip a coin. If head, receive 600 Crystals. Always head, if your Crystal is 1000 or less.
A38: Immortal Blood | B38: Tech | C38: 1000 | G38: 3 | H38: Revive 1 immortal vampire or vampire servant.
A39: Yin Yang Swap | B39: Tech | C39: 1200 | G39: 4 | H39: Swap ATK&DEF on 1 exposed unit until the end of this turn
A40: Coin on the Street | B40: Tech | C40: 0 | G40: 1 | H40: Receive 20 Crystals
...

Sheet Count
A1: Table 1
A2: Rarity | B2: Expected | C2: Percentage of Pool | D2: Notes | E2: Actual
A3: Common | B3: 52 | C3: 0.347 | D3: Filler / staple cards | E3: =_xlfn.COUNTIFS('Unit'!$J$3:$J$599,"Yes",'Unit'!$G$3:$G$599,1)+_xlfn.COUNTIFS('Trap'!$J$3:$J$544,"Yes",'Trap'!$G$3:$G$544,1)+_xlfn.COUNTIFS('Tech'!$J$3:$J$545,"Yes",'Tech'!$G$3:$G$545,1) -> 131
A4: Uncommon | B4: 48 | C4: 0.337 | D4: - | E4: =_xlfn.COUNTIFS('Unit'!$J$3:$J$599,"Yes",'Unit'!$G$3:$G$599,2)+_xlfn.COUNTIFS('Trap'!$J$3:$J$544,"Yes",'Trap'!$G$3:$G$544,2)+_xlfn.COUNTIFS('Tech'!$J$3:$J$545,"Yes",'Tech'!$G$3:$G$545,2) -> 118
A5: Rare | B5: 27 | C5: 0.167 | D5: - | E5: =_xlfn.COUNTIFS('Unit'!$J$3:$J$599,"Yes",'Unit'!$G$3:$G$599,3)+_xlfn.COUNTIFS('Trap'!$J$3:$J$544,"Yes",'Trap'!$G$3:$G$544,3)+_xlfn.COUNTIFS('Tech'!$J$3:$J$545,"Yes",'Tech'!$G$3:$G$545,3) -> 110
A6: Legendary | B6: 16 | C6: 0.1 | D6: Strong but not broken | E6: =_xlfn.COUNTIFS('Unit'!$J$3:$J$599,"Yes",'Unit'!$G$3:$G$599,4)+_xlfn.COUNTIFS('Trap'!$J$3:$J$544,"Yes",'Trap'!$G$3:$G$544,4)+_xlfn.COUNTIFS('Tech'!$J$3:$J$545,"Yes",'Tech'!$G$3:$G$545,4) -> 72
A7: Exotic | B7: 9 | C7: 0.053 | D7: Very desirable | E7: =_xlfn.COUNTIFS('Unit'!$J$3:$J$599,"Yes",'Unit'!$G$3:$G$599,5)+_xlfn.COUNTIFS('Trap'!$J$3:$J$544,"Yes",'Trap'!$G$3:$G$544,5)+_xlfn.COUNTIFS('Tech'!$J$3:$J$545,"Yes",'Tech'!$G$3:$G$545,5) -> 57
A11: Rarity | B11: Expected | E11: Actual
A12: Blightsilver | B12: 60 | E12: =_xlfn.COUNTIFS('Unit'!$N$3:$N$599,"Yes")+_xlfn.COUNTIFS('Trap'!$N$3:$N$544,"Yes")+_xlfn.COUNTIFS('Tech'!$N$3:$N$545,"Yes") -> 61
A13: Unseen Presence | B13: 60 | E13: =_xlfn.COUNTIFS('Unit'!$O$3:$O$599,"Yes")+_xlfn.COUNTIFS('Trap'!$O$3:$O$544,"Yes")+_xlfn.COUNTIFS('Tech'!$O$3:$O$545,"Yes") -> 60
A14: Wind of Dominance | B14: 60 | E14: =_xlfn.COUNTIFS('Unit'!$P$3:$P$599,"Yes")+_xlfn.COUNTIFS('Trap'!$P$3:$P$544,"Yes")+_xlfn.COUNTIFS('Tech'!$P$3:$P$545,"Yes") -> 60

Sheet Rule
A1: Table 1
B2: Old | C2: New
A3: 1 | B3: Foe | C3: foe
A4: 2 | B4: Battle calculation | C4: Reckoning
A5: 3 | B5: Cannot attack | C5: wait
A6: 4 | B6: ATK&DEF | C6: ATK&DEF
A7: 5 | B7: If head | C7: Head:
A8: 6 | B8: If tail | C8: Tail:
A9: 7 | B9: Square, grid | C9: cell
A10: 8 | B10: exposed | C10: Exposed
